Workbook

Sheet tavoli da 12
A1: nome tavolo | B1: num | C1: invitato | D1: Numero di invitati
A2: 1 | B2: 1 | C2: Chiara Ruggieri | D2: =VLOOKUP(A2,'Tabella pivot 1'!$A$2:$B$15,2) -> 2
A3: 1 | B3: 2 | C3: Daniele Fadda | D3: =VLOOKUP(A3,'Tabella pivot 1'!$A$2:$B$15,2) -> 2
A4: 2 | B4: 1 | C4: Franco Ruggieri | D4: =VLOOKUP(A4,'Tabella pivot 1'!$A$2:$B$15,2) -> 14
A5: 2 | B5: 2 | C5: Carmela Aceto | D5: =VLOOKUP(A5,'Tabella pivot 1'!$A$2:$B$15,2) -> 14
A6: 2 | B6: 3 | C6: Roberto Ruggieri | D6: =VLOOKUP(A6,'Tabella pivot 1'!$A$2:$B$15,2) -> 14
A7: 2 | B7: 4 | C7: Giovanna de Giovanni | D7: =VLOOKUP(A7,'Tabella pivot 1'!$A$2:$B$15,2) -> 14
A8: 2 | B8: 6 | C8: Girolamo Aceto | D8: =VLOOKUP(A8,'Tabella pivot 1'!$A$2:$B$15,2) -> 14
A9: 2 | B9: 7 | C9: Titti Ruberto | D9: =VLOOKUP(A9,'Tabella pivot 1'!$A$2:$B$15,2) -> 14
A10: 2 | B10: 9 | C10: Nicola Aceto | D10: =VLOOKUP(A10,'Tabella pivot 1'!$A$2:$B$15,2) -> 14
A11: 2 | B11: 10 | C11: Igino Aceto | D11: =VLOOKUP(A11,'Tabella pivot 1'!$A$2:$B$15,2) -> 14
A12: 2 | B12: 11 | C12: Mariella Capozzolo | D12: =VLOOKUP(A12,'Tabella pivot 1'!$A$2:$B$15,2) -> 14
A13: 2 | B13: 12 | C13: Vittorio Cucciniello | D13: =VLOOKUP(A13,'Tabella pivot 1'!$A$2:$B$15,2) -> 14
... A154: 14 | B154: 9 | C154: Svetlana | D154: =VLOOKUP(A154,'Tabella pivot 1'!$A$2:$B$15,2) -> 9

Sheet Tabella pivot 1
A1: nome tavolo | B1: COUNT of nome tavolo
A2: 1 | B2: 2
A3: 2 | B3: 14
A4: 3 | B4: 12
A5: 4 | B5: 12
A6: 5 | B6: 11
A7: 6 | B7: 11
A8: 7 | B8: 16
A9: 8 | B9: 11
A10: 9 | B10: 7
A11: 10 | B11: 12
A12: 11 | B12: 13
A13: 12 | B13: 13
... A15: 14 | B15: 9
A16: Totale complessivo | B16: 155

Sheet tavoli da 16
B1: nome tavolo | C1: num | D1: invitato
A2: 1 | C2: ??? | D2: BIANCA
A3: 2 | C3: ??? | D3: ROBERTINO
A4: 3 | C4: ??? | D4: ARIANNA
A5: 4 | C5: ??? | D5: BRUNO
A6: 5 | C6: A | D6: Chiara Ruggieri
A7: 6 | C7: A | D7: Daniele Fadda
A8: 7 | C8: B | D8: Franco Ruggieri
A9: 8 | C9: B | D9: Carmela Aceto
A10: 9 | C10: B | D10: Roberto Ruggieri
A11: 10 | C11: B | D11: Giovanna de Giovanni
A12: 11 | C12: B | D12: Marta Ruggieri
A13: 12 | C13: B | D13: Palmira Aceto
... A16: 15 | C16: B | D16: Geppi Aceto
A17: 16
A18: 17 | C18: B | D18: Nicola Aceto
A19: 18 | C19: B | D19: Igino Aceto
A20: 19 | C20: B | D20: Mariella Capozzolo
A21: 20 | C21: B | D21: Vittorio Cucciniello
A22: 21 | C22: B | D22: Francesco Stoppaccioli
A23: 22 | C23: B | D23: Alda Giannetti
A24: 23 | C24: C | D24: Pino Palese
A25: 24 | C25: C | D25: Beatrice Palese
A26: 25 | C26: C | D26: Gianluca Palese
A27: 26 | C27: C | D27: Lucrezia Morara Pisani
A28: 27 | C28: C | D28: Carmen Cappello
A29: 28 | C29: C | D29: Silvio Stricchi
... A55: 54 | C55: D | D55: Angelo Treviso
A56: 55 | B56: 1 | C56: E | D56: Ivana Kleva
A57: 56 | B57: 2 | C57: E | D57: Gabriele Carmignani
A58: 57 | B58: 3 | C58: E | D58: Laura Fantacci
A59: 58 | B59: 4 | C59: E | D59: Lorenzo Pacini
A60: 59 | B60: 5 | C60: E | D60: Laura Gambelli
A61: 60 | B61: 6 | C61: E | D61: Niviano La Penna
A62: 61 | B62: 7 | C62: E | D62: Martina Simonatti
A63: 62 | B63: 8 | C63: E | D63: Riccardo morandi
A64: 63 | B64: 9 | C64: E | D64: Maya Camilla Cimatti
A65: 64 | B65: 10 | C65: E | D65: Samuele Galassi
A66: 133 | B66: 11 | C66: E | D66: Natasha Trielli
A67: 65 | B67: 12 | C67: E | D67: Barbara Fortini
...

Sheet Copia di tavoli da 12
A1: 1 | B1: A | C1: 1 | D1: Chiara Ruggieri
A2: 2 | B2: A | C2: 2 | D2: Daniele Fadda
A3: 3 | B3: B | C3: 1 | D3: Franco Ruggieri
A4: 4 | B4: B | C4: 2 | D4: Carmela Aceto
A5: 5 | B5: B | C5: 3 | D5: Roberto Ruggieri
A6: 6 | B6: B | C6: 4 | D6: Giovanna de Giovanni
A7: 7 | B7: B | C7: 5 | D7: Marta Ruggieri
A8: 8 | B8: B | C8: 6 | D8: Palmira Aceto
A9: 9 | B9: B | C9: 7 | D9: Girolamo Aceto
A10: 10 | B10: B | C10: 8 | D10: Titti Ruberto
A11: 11 | B11: B | C11: 9 | D11: Geppi Aceto
A12: 12 | B12: B | C12: 10 | D12: Nicola Aceto
... A118: 156 | B118: M | C118: 7 | D118: Fidanzato Silvia Ghidoni
B119: nome tavolo | C119: num | D119: invitato
A120: 107 | D120: Francesco Fadda
A121: 108 | D121: Adonella Vecchi
A122: 109 | D122: Alessandra Fadda
A123: 110 | D123: Simone Bacci
A124: 111 | D124: Pompea Gullotta
A125: 112 | D125: Francesco Fadda
A126: 113 | D126: Giovanna Maria e Giovanni Figus
A127: 114 | D127: Pasquale Fadda
A128: 115 | D128: Maria Valentino
A129: 116 | D129: Elisabetta Fadda
A130: 117 | D130: Giovanni Lo Pinto (Fadda)
A131: 118 | D131: Luca Fadda
... A157: 149 | D157: Alberto Clerici
